Workbook

Sheet Lisez-moi
B2: Planning des épreuves BetPulse
B3: Saison 2026-2027 et suivantes. Données vérifiées sur le web le 16/10/2026.
B5: À quoi sert ce fichier
C6: Il recense toutes les épreuves proposées aux pronostics dans BetPulse : une ligne par épreuve, toutes compétitions confondues.
C7: L'application (ou un script Python) lit l'onglet Épreuves pour savoir quelles épreuves ouvrir aux pronostics et à quelles dates.
B9: Les onglets
C10: Épreuves : la table de données. C'est le seul onglet à mettre à jour au quotidien.
C11: Référentiels : la liste des sports, compétitions, statuts et genres autorisés, avec le nombre d'épreuves et la prochaine date par compétition.
C12: Lisez-moi : cette notice.
B14: Granularité retenue
C15: Sports mécaniques (F1, MotoGP, WRC) : une ligne par week-end de course ou par rallye.
C16: Sports collectifs (football, rugby, handball, hockey, volley, NFL) : une ligne par journée. NBA : une ligne par semaine, plus les temps forts (NBA Cup, All-Star, play-offs, Finales).
C17: Ski alpin et biathlon : une ligne par épreuve (une course = une ligne, hommes et femmes séparés).
C18: Golf, tennis, cyclisme : une ligne par tournoi ou par course (les courses par étapes tiennent sur une ligne, du premier au dernier jour).
B20: Règles de saisie
C21: 1. Une ligne = une épreuve. Ne pas fusionner de cellules, ne pas laisser de ligne vide au milieu de la table.
C22: 2. Les colonnes sport, competition, statut, genre et ouvert_pronos ont une liste déroulante : choisir une valeur de la liste.
C23: 3. Les dates se saisissent au format JJ/MM/AAAA. Les heures sont en heure de Paris (HH:MM).
C24: 4. L'identifiant (colonne id) ne se modifie jamais. Pour une nouvelle épreuve : CODE-SAISON-NUMÉRO, le code étant celui de l'onglet Référentiels (ex. F1-2027-025).
C25: 5. Une épreuve annulée ou reportée n'est pas supprimée : changer son statut et préciser la raison dans notes.
C26: 6. À chaque vérification, mettre à jour source_url et date_verification.
C27: 7. La colonne avancement se calcule seule. Pour une nouvelle ligne, recopier la formule de la ligne du dessus (dans Google Sheets, elle s'étend toute seule).
B29: Code couleur
C30: Ligne grisée : épreuve terminée.
C31: Statut en orange : date provisoire. Statut en rouge : date à confirmer, reportée ou annulée.
B33: Lecture en Python
C34: Voir planning/lire_planning.py dans le dépôt BetPulse. Le script lit l'onglet Épreuves (export CSV ou API Google Sheets) et renvoie un DataFrame pandas.
B36: Dictionnaire des colonnes (onglet Épreuves)
B37: Colonne | C37: Contenu
B38: id | C38: Identifiant unique et stable : CODE-SAISON-NUMÉRO. Ne jamais le modifier une fois créé (le code Python s'en sert comme clé).
B39: sport | C39: Sport, choisi dans la liste (onglet Référentiels).
B40: competition | C40: Compétition, choisie dans la liste (onglet Référentiels).
B41: saison | C41: Saison : 2026-2027 pour les sports d'hiver et les championnats à cheval sur deux années, 2026 ou 2027 pour les calendriers sur une année civile.
B42: phase | C42: Phase de la compétition : saison régulière, phase de ligue, play-offs, finale, discipline (ski, biathlon)...
B43: manche | C43: Numéro de journée, de semaine ou de manche. Vide si la phase n'est pas numérotée.
B44: intitule | C44: Libellé lisible de l'épreuve, tel qu'il sera affiché dans BetPulse.
B45: date_debut | C45: Premier jour de l'épreuve (format JJ/MM/AAAA).
B46: date_fin | C46: Dernier jour de l'épreuve. Identique à date_debut pour une épreuve d'un jour.
B47: heure_debut | C47: Heure de départ, heure de Paris (HH:MM). Renseignée seulement si elle est officielle.
B48: fuseau | C48: Fuseau horaire de heure_debut. Toujours Europe/Paris.
...

Sheet Épreuves
A1: id | B1: sport | C1: competition | D1: saison | E1: phase | F1: manche | G1: intitule | H1: date_debut | I1: date_fin | J1: heure_debut | K1: fuseau | L1: lieu | M1: pays | N1: genre | O1: statut | P1: ouvert_pronos | Q1: source_url | R1: date_verification | S1: notes | T1: avancement
A2: L1-2627-001 | B2: Football | C2: Ligue 1 | D2: 2026-2027 | E2: Saison régulière | F2: 1 | G2: Ligue 1 – Journée 1 | H2: 46255 | I2: 46257 | K2: Europe/Paris | M2: France | N2: Hommes | O2: Officiel | P2: Oui | Q2: https://ligue1.com/fr/articles/l1_article_5284-ligue-1-mc-donald-s-le-calendrier-de-la-saison-26-27 | R2: 46311 | S2: Ouverture de la saison (21-23 août) | T2: =IF(H2="","",IF(MAX(H2,I2)<TODAY(),"Terminé",IF(H2<=TODAY(),"En cours","À venir")))
A3: L1-2627-002 | B3: Football | C3: Ligue 1 | D3: 2026-2027 | E3: Saison régulière | F3: 2 | G3: Ligue 1 – Journée 2 | H3: 46262 | I3: 46264 | K3: Europe/Paris | M3: France | N3: Hommes | O3: Officiel | P3: Oui | Q3: https://ligue1.com/fr/articles/l1_article_5435-programmation-tv-des-2-premieres-journees-de-ligue-1-mc-donald-s-2627 | R3: 46311 | S3: Week-end du 29 août ; jours exacts par match non vérifiés | T3: =IF(H3="","",IF(MAX(H3,I3)<TODAY(),"Terminé",IF(H3<=TODAY(),"En cours","À venir")))
A4: L1-2627-003 | B4: Football | C4: Ligue 1 | D4: 2026-2027 | E4: Saison régulière | F4: 3 | G4: Ligue 1 – Journée 3 | H4: 46268 | I4: 46271 | K4: Europe/Paris | M4: France | N4: Hommes | O4: Officiel | P4: Oui | Q4: https://ligue1.com/fr/articles/l1_article_5572-programmation-tv-j3-ligue-1-mc-donald-s-2627 | R4: 46311 | S4: Ouverture le jeudi 3 septembre (Toulouse–LOSC) | T4: =IF(H4="","",IF(MAX(H4,I4)<TODAY(),"Terminé",IF(H4<=TODAY(),"En cours","À venir")))
A5: L1-2627-004 | B5: Football | C5: Ligue 1 | D5: 2026-2027 | E5: Saison régulière | F5: 4 | G5: Ligue 1 – Journée 4 | H5: 46276 | I5: 46278 | K5: Europe/Paris | M5: France | N5: Hommes | O5: Officiel | P5: Oui | Q5: https://ligue1.com/fr/articles/l1_article_5562-programmation-tv-j4-2 | R5: 46311 | T5: =IF(H5="","",IF(MAX(H5,I5)<TODAY(),"Terminé",IF(H5<=TODAY(),"En cours","À venir")))
A6: L1-2627-005 | B6: Football | C6: Ligue 1 | D6: 2026-2027 | E6: Saison régulière | F6: 5 | G6: Ligue 1 – Journée 5 | H6: 46283 | I6: 46285 | K6: Europe/Paris | M6: France | N6: Hommes | O6: Officiel | P6: Oui | Q6: https://ligue1.com/fr/articles/l1_article_5790-programmation-tv-j5-ligue-1-2026-2027 | R6: 46311 | S6: Trêve internationale ensuite (21 sept.–6 oct.) | T6: =IF(H6="","",IF(MAX(H6,I6)<TODAY(),"Terminé",IF(H6<=TODAY(),"En cours","À venir")))
A7: L1-2627-006 | B7: Football | C7: Ligue 1 | D7: 2026-2027 | E7: Saison régulière | F7: 6 | G7: Ligue 1 – Journée 6 | H7: 46304 | I7: 46306 | K7: Europe/Paris | M7: France | N7: Hommes | O7: Officiel | P7: Oui | Q7: https://ligue1.com/fr/articles/l1_article_5797-programmations-tv-j6-j7-et-j8-l1-2627 | R7: 46311 | T7: =IF(H7="","",IF(MAX(H7,I7)<TODAY(),"Terminé",IF(H7<=TODAY(),"En cours","À venir")))
A8: L1-2627-007 | B8: Football | C8: Ligue 1 | D8: 2026-2027 | E8: Saison régulière | F8: 7 | G8: Ligue 1 – Journée 7 | H8: 46311 | I8: 46313 | K8: Europe/Paris | M8: France | N8: Hommes | O8: Officiel | P8: Oui | Q8: https://ligue1.com/fr/articles/l1_article_5797-programmations-tv-j6-j7-et-j8-l1-2627 | R8: 46311 | T8: =IF(H8="","",IF(MAX(H8,I8)<TODAY(),"Terminé",IF(H8<=TODAY(),"En cours","À venir")))
A9: L1-2627-008 | B9: Football | C9: Ligue 1 | D9: 2026-2027 | E9: Saison régulière | F9: 8 | G9: Ligue 1 – Journée 8 | H9: 46318 | I9: 46320 | K9: Europe/Paris | M9: France | N9: Hommes | O9: Officiel | P9: Oui | Q9: https://ligue1.com/fr/articles/l1_article_5797-programmations-tv-j6-j7-et-j8-l1-2627 | R9: 46311 | T9: =IF(H9="","",IF(MAX(H9,I9)<TODAY(),"Terminé",IF(H9<=TODAY(),"En cours","À venir")))
A10: L1-2627-009 | B10: Football | C10: Ligue 1 | D10: 2026-2027 | E10: Saison régulière | F10: 9 | G10: Ligue 1 – Journée 9 | H10: 46325 | I10: 46327 | K10: Europe/Paris | M10: France | N10: Hommes | O10: Officiel | P10: Oui | Q10: https://ligue1.com/fr/articles/l1_article_5805-programmation-tv-j9-1 | R10: 46311 | T10: =IF(H10="","",IF(MAX(H10,I10)<TODAY(),"Terminé",IF(H10<=TODAY(),"En cours","À venir")))
A11: L1-2627-010 | B11: Football | C11: Ligue 1 | D11: 2026-2027 | E11: Saison régulière | F11: 10 | G11: Ligue 1 – Journée 10 | H11: 46332 | I11: 46334 | K11: Europe/Paris | M11: France | N11: Hommes | O11: Officiel | P11: Oui | Q11: https://ligue1.com/fr/articles/l1_article_5839-programmation-tv-j10-j11-ligue-1-2026-2027 | R11: 46311 | T11: =IF(H11="","",IF(MAX(H11,I11)<TODAY(),"Terminé",IF(H11<=TODAY(),"En cours","À venir")))
A12: L1-2627-011 | B12: Football | C12: Ligue 1 | D12: 2026-2027 | E12: Saison régulière | F12: 11 | G12: Ligue 1 – Journée 11 | H12: 46346 | I12: 46348 | K12: Europe/Paris | M12: France | N12: Hommes | O12: Provisoire | P12: Oui | Q12: https://ligue1.com/fr/articles/l1_article_5839-programmation-tv-j10-j11-ligue-1-2026-2027 | R12: 46311 | S12: Programmation TV publiée (J10-J11) ; jours exacts non vérifiés | T12: =IF(H12="","",IF(MAX(H12,I12)<TODAY(),"Terminé",IF(H12<=TODAY(),"En cours","À venir")))
A13: L1-2627-012 | B13: Football | C13: Ligue 1 | D13: 2026-2027 | E13: Saison régulière | F13: 12 | G13: Ligue 1 – Journée 12 | H13: 46353 | I13: 46355 | K13: Europe/Paris | M13: France | N13: Hommes | O13: Provisoire | P13: Oui | Q13: https://www.lfp.fr/assets/L1_MD_2627_CALENDRIER_SOMBRE_920e8f5afd.pdf | R13: 46311 | S13: Programmation TV non publiée | T13: =IF(H13="","",IF(MAX(H13,I13)<TODAY(),"Terminé",IF(H13<=TODAY(),"En cours","À venir")))
A14: L1-2627-013 | B14: Football | C14: Ligue 1 | D14: 2026-2027 | E14: Saison régulière | F14: 13 | G14: Ligue 1 – Journée 13 | H14: 46360 | I14: 46362 | K14: Europe/Paris | M14: France | N14: Hommes | O14: Provisoire | P14: Oui | Q14: https://www.lfp.fr/assets/L1_MD_2627_CALENDRIER_SOMBRE_920e8f5afd.pdf | R14: 46311 | S14: Programmation TV non publiée | T14: =IF(H14="","",IF(MAX(H14,I14)<TODAY(),"Terminé",IF(H14<=TODAY(),"En cours","À venir")))
A15: L1-2627-014 | B15: Football | C15: Ligue 1 | D15: 2026-2027 | E15: Saison régulière | F15: 14 | G15: Ligue 1 – Journée 14 | H15: 46367 | I15: 46369 | K15: Europe/Paris | M15: France | N15: Hommes | O15: Provisoire | P15: Oui | Q15: https://www.lfp.fr/assets/L1_MD_2627_CALENDRIER_SOMBRE_920e8f5afd.pdf | R15: 46311 | S15: Dernière journée de 2026 (trêve hivernale) ; programmation TV non publiée | T15: =IF(H15="","",IF(MAX(H15,I15)<TODAY(),"Terminé",IF(H15<=TODAY(),"En cours","À venir")))
A16: L1-2627-015 | B16: Football | C16: Ligue 1 | D16: 2026-2027 | E16: Saison régulière | F16: 15 | G16: Ligue 1 – Journée 15 | H16: 46389 | I16: 46390 | K16: Europe/Paris | M16: France | N16: Hommes | O16: Provisoire | P16: Oui | Q16: https://www.lfp.fr/assets/L1_MD_2627_CALENDRIER_SOMBRE_920e8f5afd.pdf | R16: 46311 | S16: Reprise après la trêve ; week-end du 2 janvier (LFP) ; programmation TV non publiée | T16: =IF(H16="","",IF(MAX(H16,I16)<TODAY(),"Terminé",IF(H16<=TODAY(),"En cours","À venir")))
A17: L1-2627-016 | B17: Football | C17: Ligue 1 | D17: 2026-2027 | E17: Saison régulière | F17: 16 | G17: Ligue 1 – Journée 16 | H17: 46402 | I17: 46404 | K17: Europe/Paris | M17: France | N17: Hommes | O17: Provisoire | P17: Oui | Q17: https://www.lfp.fr/assets/L1_MD_2627_CALENDRIER_SOMBRE_920e8f5afd.pdf | R17: 46311 | S17: Programmation TV non publiée | T17: =IF(H17="","",IF(MAX(H17,I17)<TODAY(),"Terminé",IF(H17<=TODAY(),"En cours","À venir")))
A18: L1-2627-017 | B18: Football | C18: Ligue 1 | D18: 2026-2027 | E18: Saison régulière | F18: 17 | G18: Ligue 1 – Journée 17 | H18: 46409 | I18: 46411 | K18: Europe/Paris | M18: France | N18: Hommes | O18: Provisoire | P18: Oui | Q18: https://www.lfp.fr/assets/L1_MD_2627_CALENDRIER_SOMBRE_920e8f5afd.pdf | R18: 46311 | S18: Programmation TV non publiée | T18: =IF(H18="","",IF(MAX(H18,I18)<TODAY(),"Terminé",IF(H18<=TODAY(),"En cours","À venir")))
A19: L1-2627-018 | B19: Football | C19: Ligue 1 | D19: 2026-2027 | E19: Saison régulière | F19: 18 | G19: Ligue 1 – Journée 18 | H19: 46416 | I19: 46418 | K19: Europe/Paris | M19: France | N19: Hommes | O19: Provisoire | P19: Oui | Q19: https://www.lfp.fr/assets/L1_MD_2627_CALENDRIER_SOMBRE_920e8f5afd.pdf | R19: 46311 | S19: Programmation TV non publiée | T19: =IF(H19="","",IF(MAX(H19,I19)<TODAY(),"Terminé",IF(H19<=TODAY(),"En cours","À venir")))
A20: L1-2627-019 | B20: Football | C20: Ligue 1 | D20: 2026-2027 | E20: Saison régulière | F20: 19 | G20: Ligue 1 – Journée 19 | H20: 46423 | I20: 46425 | K20: Europe/Paris | M20: France | N20: Hommes | O20: Provisoire | P20: Oui | Q20: https://www.lfp.fr/assets/L1_MD_2627_CALENDRIER_SOMBRE_920e8f5afd.pdf | R20: 46311 | S20: Programmation TV non publiée | T20: =IF(H20="","",IF(MAX(H20,I20)<TODAY(),"Terminé",IF(H20<=TODAY(),"En cours","À venir")))
A21: L1-2627-020 | B21: Football | C21: Ligue 1 | D21: 2026-2027 | E21: Saison régulière | F21: 20 | G21: Ligue 1 – Journée 20 | H21: 46430 | I21: 46432 | K21: Europe/Paris | M21: France | N21: Hommes | O21: Provisoire | P21: Oui | Q21: https://www.lfp.fr/assets/L1_MD_2627_CALENDRIER_SOMBRE_920e8f5afd.pdf | R21: 46311 | S21: Programmation TV non publiée | T21: =IF(H21="","",IF(MAX(H21,I21)<TODAY(),"Terminé",IF(H21<=TODAY(),"En cours","À venir")))
A22: L1-2627-021 | B22: Football | C22: Ligue 1 | D22: 2026-2027 | E22: Saison régulière | F22: 21 | G22: Ligue 1 – Journée 21 | H22: 46437 | I22: 46439 | K22: Europe/Paris | M22: France | N22: Hommes | O22: Provisoire | P22: Oui | Q22: https://www.lfp.fr/assets/L1_MD_2627_CALENDRIER_SOMBRE_920e8f5afd.pdf | R22: 46311 | S22: Programmation TV non publiée | T22: =IF(H22="","",IF(MAX(H22,I22)<TODAY(),"Terminé",IF(H22<=TODAY(),"En cours","À venir")))
A23: L1-2627-022 | B23: Football | C23: Ligue 1 | D23: 2026-2027 | E23: Saison régulière | F23: 22 | G23: Ligue 1 – Journée 22 | H23: 46444 | I23: 46446 | K23: Europe/Paris | M23: France | N23: Hommes | O23: Provisoire | P23: Oui | Q23: https://www.lfp.fr/assets/L1_MD_2627_CALENDRIER_SOMBRE_920e8f5afd.pdf | R23: 46311 | S23: Programmation TV non publiée | T23: =IF(H23="","",IF(MAX(H23,I23)<TODAY(),"Terminé",IF(H23<=TODAY(),"En cours","À venir")))
... A35: L1-2627-034 | B35: Football | C35: Ligue 1 | D35: 2026-2027 | E35: Saison régulière | F35: 34 | G35: Ligue 1 – Journée 34 | H35: 46536 | I35: 46536 | K35: Europe/Paris | M35: France | N35: Hommes | O35: Officiel | P35: Oui | Q35: https://ligue1.com/fr/articles/l1_article_5284-ligue-1-mc-donald-s-le-calendrier-de-la-saison-26-27 | R35: 46311 | S35: Dernière journée, multiplex le samedi ; horaire non vérifié | T35: =IF(H35="","",IF(MAX(H35,I35)<TODAY(),"Terminé",IF(H35<=TODAY(),"En cours","À venir")))
A36: L1-2627-035 | B36: Football | C36: Ligue 1 | D36: 2026-2027 | E36: Barrages | G36: Ligue 1 – Barrage d'accession L1/L2 | H36: 46541 | I36: 46544 | K36: Europe/Paris | M36: France | N36: Hommes | O36: Officiel | P36: Oui | Q36: https://www.lfp.fr/article/publication-du-calendrier-general-de-la-ligue-2-bkt-pour-la-saison-2026-2027 | R36: 46311 | S36: 16e de L1 vs vainqueur des play-offs L2 ; aller jeudi 3 juin, retour dimanche 6 juin | T36: =IF(H36="","",IF(MAX(H36,I36)<TODAY(),"Terminé",IF(H36<=TODAY(),"En cours","À venir")))
A37: L2-2627-001 | B37: Football | C37: Ligue 2 | D37: 2026-2027 | E37: Saison régulière | F37: 1 | G37: Ligue 2 – Journée 1 | H37: 46242 | I37: 46242 | K37: Europe/Paris | M37: France | N37: Hommes | O37: Officiel | P37: Oui | Q37: https://ligue1.com/fr/articles/l1_article_5291-programmation-tv-des-2-premieres-journees-de-ligue-2-bkt | R37: 46311 | S37: Journée jouée le samedi (multiplex + affiche à 20h45) | T37: =IF(H37="","",IF(MAX(H37,I37)<TODAY(),"Terminé",IF(H37<=TODAY(),"En cours","À venir")))
A38: L2-2627-002 | B38: Football | C38: Ligue 2 | D38: 2026-2027 | E38: Saison régulière | F38: 2 | G38: Ligue 2 – Journée 2 | H38: 46248 | I38: 46248 | K38: Europe/Paris | M38: France | N38: Hommes | O38: Officiel | P38: Oui | Q38: https://ligue1.com/fr/articles/l1_article_5291-programmation-tv-des-2-premieres-journees-de-ligue-2-bkt | R38: 46311 | S38: Multiplex avancé du samedi 15 au vendredi 14 août | T38: =IF(H38="","",IF(MAX(H38,I38)<TODAY(),"Terminé",IF(H38<=TODAY(),"En cours","À venir")))
A39: L2-2627-003 | B39: Football | C39: Ligue 2 | D39: 2026-2027 | E39: Saison régulière | F39: 3 | G39: Ligue 2 – Journée 3 | H39: 46255 | I39: 46258 | K39: Europe/Paris | M39: France | N39: Hommes | O39: Officiel | P39: Oui | Q39: https://www.lfp.fr/article/ligue-2-bkt-le-calendrier-de-la-saison-2026-2027 | R39: 46311 | S39: Week-end LFP (ven.–lun.) ; jours exacts par match non vérifiés | T39: =IF(H39="","",IF(MAX(H39,I39)<TODAY(),"Terminé",IF(H39<=TODAY(),"En cours","À venir")))
A40: L2-2627-004 | B40: Football | C40: Ligue 2 | D40: 2026-2027 | E40: Saison régulière | F40: 4 | G40: Ligue 2 – Journée 4 | H40: 46262 | I40: 46265 | K40: Europe/Paris | M40: France | N40: Hommes | O40: Officiel | P40: Oui | Q40: https://www.lfp.fr/article/ligue-2-bkt-le-calendrier-de-la-saison-2026-2027 | R40: 46311 | S40: Week-end LFP (ven.–lun.) ; jours exacts par match non vérifiés | T40: =IF(H40="","",IF(MAX(H40,I40)<TODAY(),"Terminé",IF(H40<=TODAY(),"En cours","À venir")))
A41: L2-2627-005 | B41: Football | C41: Ligue 2 | D41: 2026-2027 | E41: Saison régulière | F41: 5 | G41: Ligue 2 – Journée 5 | H41: 46269 | I41: 46272 | K41: Europe/Paris | M41: France | N41: Hommes | O41: Officiel | P41: Oui | Q41: https://www.lfp.fr/article/ligue-2-bkt-le-calendrier-de-la-saison-2026-2027 | R41: 46311 | S41: Week-end LFP (ven.–lun.) ; jours exacts par match non vérifiés | T41: =IF(H41="","",IF(MAX(H41,I41)<TODAY(),"Terminé",IF(H41<=TODAY(),"En cours","À venir")))
A42: L2-2627-006 | B42: Football | C42: Ligue 2 | D42: 2026-2027 | E42: Saison régulière | F42: 6 | G42: Ligue 2 – Journée 6 | H42: 46276 | I42: 46279 | K42: Europe/Paris | M42: France | N42: Hommes | O42: Officiel | P42: Oui | Q42: https://www.lfp.fr/article/ligue-2-bkt-le-calendrier-de-la-saison-2026-2027 | R42: 46311 | S42: Week-end LFP (ven.–lun.) ; jours exacts par match non vérifiés | T42: =IF(H42="","",IF(MAX(H42,I42)<TODAY(),"Terminé",IF(H42<=TODAY(),"En cours","À venir")))
A43: L2-2627-007 | B43: Football | C43: Ligue 2 | D43: 2026-2027 | E43: Saison régulière | F43: 7 | G43: Ligue 2 – Journée 7 | H43: 46283 | I43: 46286 | K43: Europe/Paris | M43: France | N43: Hommes | O43: Officiel | P43: Oui | Q43: https://www.lfp.fr/article/ligue-2-bkt-le-calendrier-de-la-saison-2026-2027 | R43: 46311 | S43: Week-end LFP (ven.–lun.) ; jours exacts par match non vérifiés | T43: =IF(H43="","",IF(MAX(H43,I43)<TODAY(),"Terminé",IF(H43<=TODAY(),"En cours","À venir")))
A44: L2-2627-008 | B44: Football | C44: Ligue 2 | D44: 2026-2027 | E44: Saison régulière | F44: 8 | G44: Ligue 2 – Journée 8 | H44: 46304 | I44: 46307 | K44: Europe/Paris | M44: France | N44: Hommes | O44: Officiel | P44: Oui | Q44: https://ligue1.com/fr/articles/l1_article_5652-programmation-tv-j8-l2-2627 | R44: 46311 | S44: Vendredi multiplex, samedi, lundi (programmation TV) | T44: =IF(H44="","",IF(MAX(H44,I44)<TODAY(),"Terminé",IF(H44<=TODAY(),"En cours","À venir")))
A45: L2-2627-009 | B45: Football | C45: Ligue 2 | D45: 2026-2027 | E45: Saison régulière | F45: 9 | G45: Ligue 2 – Journée 9 | H45: 46311 | I45: 46314 | K45: Europe/Paris | M45: France | N45: Hommes | O45: Officiel | P45: Oui | Q45: https://ligue1.com/fr/articles/l1_article_5695-programmation-tv-j9-ligue-2-2026-2027 | R45: 46311 | S45: Vendredi multiplex, samedi, lundi (programmation TV) | T45: =IF(H45="","",IF(MAX(H45,I45)<TODAY(),"Terminé",IF(H45<=TODAY(),"En cours","À venir")))
A46: L2-2627-010 | B46: Football | C46: Ligue 2 | D46: 2026-2027 | E46: Saison régulière | F46: 10 | G46: Ligue 2 – Journée 10 | H46: 46318 | I46: 46321 | K46: Europe/Paris | M46: France | N46: Hommes | O46: Officiel | P46: Oui | Q46: https://ligue1.com/fr/articles/l1_article_5749-programmation-tv-j10-1 | R46: 46311 | S46: Multiplex vendredi 23 oct. ; date du dernier match non vérifiée | T46: =IF(H46="","",IF(MAX(H46,I46)<TODAY(),"Terminé",IF(H46<=TODAY(),"En cours","À venir")))
A47: L2-2627-011 | B47: Football | C47: Ligue 2 | D47: 2026-2027 | E47: Saison régulière | F47: 11 | G47: Ligue 2 – Journée 11 | H47: 46325 | I47: 46328 | K47: Europe/Paris | M47: France | N47: Hommes | O47: Officiel | P47: Oui | Q47: https://ligue1.com/fr/articles/l1_article_5803-programmation-tv-j11-l2-2627 | R47: 46311 | S47: Vendredi multiplex, samedi, lundi (programmation TV) | T47: =IF(H47="","",IF(MAX(H47,I47)<TODAY(),"Terminé",IF(H47<=TODAY(),"En cours","À venir")))
A48: L2-2627-012 | B48: Football | C48: Ligue 2 | D48: 2026-2027 | E48: Saison régulière | F48: 12 | G48: Ligue 2 – Journée 12 | H48: 46332 | I48: 46335 | K48: Europe/Paris | M48: France | N48: Hommes | O48: Provisoire | P48: Oui | Q48: https://www.lfp.fr/article/ligue-2-bkt-le-calendrier-de-la-saison-2026-2027 | R48: 46311 | S48: Week-end nominal ven.–lun. ; programmation TV non publiée | T48: =IF(H48="","",IF(MAX(H48,I48)<TODAY(),"Terminé",IF(H48<=TODAY(),"En cours","À venir")))
... A70: L2-2627-034 | B70: Football | C70: Ligue 2 | D70: 2026-2027 | E70: Saison régulière | F70: 34 | G70: Ligue 2 – Journée 34 | H70: 46529 | I70: 46529 | K70: Europe/Paris | M70: France | N70: Hommes | O70: Officiel | P70: Oui | Q70: https://www.lfp.fr/article/publication-du-calendrier-general-de-la-ligue-2-bkt-pour-la-saison-2026-2027 | R70: 46311 | S70: Dernière journée, multiplex le samedi ; horaire non vérifié | T70: =IF(H70="","",IF(MAX(H70,I70)<TODAY(),"Terminé",IF(H70<=TODAY(),"En cours","À venir")))
A71: L2-2627-035 | B71: Football | C71: Ligue 2 | D71: 2026-2027 | E71: Play-offs | G71: Ligue 2 – Play-off 1 (4e vs 5e) | H71: 46532 | I71: 46532 | K71: Europe/Paris | M71: France | N71: Hommes | O71: Officiel | P71: Oui | Q71: https://www.lfp.fr/article/publication-du-calendrier-general-de-la-ligue-2-bkt-pour-la-saison-2026-2027 | R71: 46311 | S71: Mardi 25 mai | T71: =IF(H71="","",IF(MAX(H71,I71)<TODAY(),"Terminé",IF(H71<=TODAY(),"En cours","À venir")))
A72: L2-2627-036 | B72: Football | C72: Ligue 2 | D72: 2026-2027 | E72: Play-offs | G72: Ligue 2 – Play-off 2 (3e vs vainqueur PO1) | H72: 46535 | I72: 46535 | K72: Europe/Paris | M72: France | N72: Hommes | O72: Officiel | P72: Oui | Q72: https://www.lfp.fr/article/publication-du-calendrier-general-de-la-ligue-2-bkt-pour-la-saison-2026-2027 | R72: 46311 | S72: Vendredi 28 mai ; le vainqueur dispute le barrage L1/L2 (3 et 6 juin) | T72: =IF(H72="","",IF(MAX(H72,I72)<TODAY(),"Terminé",IF(H72<=TODAY(),"En cours","À venir")))
...

Sheet Référentiels
A1: code | B1: sport | C1: competition | D1: granularite | E1: source_officielle | F1: nb_epreuves | G1: prochaine_epreuve | H1: sports | J1: statuts | K1: genres | L1: oui_non
A2: L1 | B2: Football | C2: Ligue 1 | D2: 1 ligne par journée | E2: https://ligue1.com | F2: =COUNTIF('Épreuves'!$C$2:$C$5000,C2) | G2: =IFERROR(1/(1/_xlfn.MINIFS('Épreuves'!$H$2:$H$5000,'Épreuves'!$C$2:$C$5000,C2,'Épreuves'!$H$2:$H$5000,">="&TODAY())),"") | H2: Basketball | J2: Officiel | K2: Hommes | L2: Oui
A3: L2 | B3: Football | C3: Ligue 2 | D3: 1 ligne par journée | E3: https://www.ligue2.fr | F3: =COUNTIF('Épreuves'!$C$2:$C$5000,C3) | G3: =IFERROR(1/(1/_xlfn.MINIFS('Épreuves'!$H$2:$H$5000,'Épreuves'!$C$2:$C$5000,C3,'Épreuves'!$H$2:$H$5000,">="&TODAY())),"") | H3: Biathlon | J3: Provisoire | K3: Femmes | L3: Non
A4: LIGA | B4: Football | C4: LaLiga | D4: 1 ligne par journée | E4: https://www.laliga.com | F4: =COUNTIF('Épreuves'!$C$2:$C$5000,C4) | G4: =IFERROR(1/(1/_xlfn.MINIFS('Épreuves'!$H$2:$H$5000,'Épreuves'!$C$2:$C$5000,C4,'Épreuves'!$H$2:$H$5000,">="&TODAY())),"") | H4: Cyclisme sur route | J4: À confirmer | K4: Mixte
A5: EPL | B5: Football | C5: Premier League | D5: 1 ligne par journée | E5: https://www.premierleague.com | F5: =COUNTIF('Épreuves'!$C$2:$C$5000,C5) | G5: =IFERROR(1/(1/_xlfn.MINIFS('Épreuves'!$H$2:$H$5000,'Épreuves'!$C$2:$C$5000,C5,'Épreuves'!$H$2:$H$5000,">="&TODAY())),"") | H5: Football | J5: Reporté
A6: UCL | B6: Football | C6: UEFA Champions League | D6: 1 ligne par journée ou par match aller/retour | E6: https://www.uefa.com/uefachampionsleague | F6: =COUNTIF('Épreuves'!$C$2:$C$5000,C6) | G6: =IFERROR(1/(1/_xlfn.MINIFS('Épreuves'!$H$2:$H$5000,'Épreuves'!$C$2:$C$5000,C6,'Épreuves'!$H$2:$H$5000,">="&TODAY())),"") | H6: Football américain | J6: Annulé
A7: UNL | B7: Football | C7: UEFA Nations League | D7: 1 ligne par journée ou par tour | E7: https://www.uefa.com/uefanationsleague | F7: =COUNTIF('Épreuves'!$C$2:$C$5000,C7) | G7: =IFERROR(1/(1/_xlfn.MINIFS('Épreuves'!$H$2:$H$5000,'Épreuves'!$C$2:$C$5000,C7,'Épreuves'!$H$2:$H$5000,">="&TODAY())),"") | H7: Golf
A8: T14 | B8: Rugby | C8: Top 14 | D8: 1 ligne par journée | E8: https://top14.lnr.fr | F8: =COUNTIF('Épreuves'!$C$2:$C$5000,C8) | G8: =IFERROR(1/(1/_xlfn.MINIFS('Épreuves'!$H$2:$H$5000,'Épreuves'!$C$2:$C$5000,C8,'Épreuves'!$H$2:$H$5000,">="&TODAY())),"") | H8: Handball
A9: PD2 | B9: Rugby | C9: Pro D2 | D9: 1 ligne par journée | E9: https://prod2.lnr.fr | F9: =COUNTIF('Épreuves'!$C$2:$C$5000,C9) | G9: =IFERROR(1/(1/_xlfn.MINIFS('Épreuves'!$H$2:$H$5000,'Épreuves'!$C$2:$C$5000,C9,'Épreuves'!$H$2:$H$5000,">="&TODAY())),"") | H9: Hockey sur glace
A10: CC | B10: Rugby | C10: Champions Cup | D10: 1 ligne par journée ou par tour | E10: https://www.epcrugby.com | F10: =COUNTIF('Épreuves'!$C$2:$C$5000,C10) | G10: =IFERROR(1/(1/_xlfn.MINIFS('Épreuves'!$H$2:$H$5000,'Épreuves'!$C$2:$C$5000,C10,'Épreuves'!$H$2:$H$5000,">="&TODAY())),"") | H10: Moto
A11: SL | B11: Handball | C11: StarLigue | D11: 1 ligne par journée | E11: https://www.lnh.fr | F11: =COUNTIF('Épreuves'!$C$2:$C$5000,C11) | G11: =IFERROR(1/(1/_xlfn.MINIFS('Épreuves'!$H$2:$H$5000,'Épreuves'!$C$2:$C$5000,C11,'Épreuves'!$H$2:$H$5000,">="&TODAY())),"") | H11: Rallye
A12: MAG | B12: Hockey sur glace | C12: Ligue Magnus | D12: 1 ligne par journée ou par tour de play-offs | E12: https://www.hockeyfrance.com | F12: =COUNTIF('Épreuves'!$C$2:$C$5000,C12) | G12: =IFERROR(1/(1/_xlfn.MINIFS('Épreuves'!$H$2:$H$5000,'Épreuves'!$C$2:$C$5000,C12,'Épreuves'!$H$2:$H$5000,">="&TODAY())),"") | H12: Rugby
A13: SPK | B13: Volley-ball | C13: Marmara SpikeLigue | D13: 1 ligne par journée ou par tour de play-offs | E13: https://www.lnv.fr | F13: =COUNTIF('Épreuves'!$C$2:$C$5000,C13) | G13: =IFERROR(1/(1/_xlfn.MINIFS('Épreuves'!$H$2:$H$5000,'Épreuves'!$C$2:$C$5000,C13,'Épreuves'!$H$2:$H$5000,">="&TODAY())),"") | H13: Ski alpin
A14: NBA | B14: Basketball | C14: NBA | D14: 1 ligne par semaine + temps forts | E14: https://www.nba.com | F14: =COUNTIF('Épreuves'!$C$2:$C$5000,C14) | G14: =IFERROR(1/(1/_xlfn.MINIFS('Épreuves'!$H$2:$H$5000,'Épreuves'!$C$2:$C$5000,C14,'Épreuves'!$H$2:$H$5000,">="&TODAY())),"") | H14: Sport automobile
A15: NFL | B15: Football américain | C15: NFL | D15: 1 ligne par semaine (Week) | E15: https://www.nfl.com | F15: =COUNTIF('Épreuves'!$C$2:$C$5000,C15) | G15: =IFERROR(1/(1/_xlfn.MINIFS('Épreuves'!$H$2:$H$5000,'Épreuves'!$C$2:$C$5000,C15,'Épreuves'!$H$2:$H$5000,">="&TODAY())),"") | H15: Tennis
A16: PGA | B16: Golf | C16: PGA Tour | D16: 1 ligne par tournoi | E16: https://www.pgatour.com | F16: =COUNTIF('Épreuves'!$C$2:$C$5000,C16) | G16: =IFERROR(1/(1/_xlfn.MINIFS('Épreuves'!$H$2:$H$5000,'Épreuves'!$C$2:$C$5000,C16,'Épreuves'!$H$2:$H$5000,">="&TODAY())),"") | H16: Volley-ball
A17: F1 | B17: Sport automobile | C17: Formule 1 | D17: 1 ligne par week-end de Grand Prix | E17: https://www.formula1.com | F17: =COUNTIF('Épreuves'!$C$2:$C$5000,C17) | G17: =IFERROR(1/(1/_xlfn.MINIFS('Épreuves'!$H$2:$H$5000,'Épreuves'!$C$2:$C$5000,C17,'Épreuves'!$H$2:$H$5000,">="&TODAY())),"")
A18: MGP | B18: Moto | C18: MotoGP | D18: 1 ligne par week-end de Grand Prix | E18: https://www.motogp.com | F18: =COUNTIF('Épreuves'!$C$2:$C$5000,C18) | G18: =IFERROR(1/(1/_xlfn.MINIFS('Épreuves'!$H$2:$H$5000,'Épreuves'!$C$2:$C$5000,C18,'Épreuves'!$H$2:$H$5000,">="&TODAY())),"")
A19: WRC | B19: Rallye | C19: WRC | D19: 1 ligne par rallye | E19: https://www.wrc.com | F19: =COUNTIF('Épreuves'!$C$2:$C$5000,C19) | G19: =IFERROR(1/(1/_xlfn.MINIFS('Épreuves'!$H$2:$H$5000,'Épreuves'!$C$2:$C$5000,C19,'Épreuves'!$H$2:$H$5000,">="&TODAY())),"")
A20: GC | B20: Tennis | C20: Grand Chelem | D20: 1 ligne par tournoi | E20: https://www.itftennis.com | F20: =COUNTIF('Épreuves'!$C$2:$C$5000,C20) | G20: =IFERROR(1/(1/_xlfn.MINIFS('Épreuves'!$H$2:$H$5000,'Épreuves'!$C$2:$C$5000,C20,'Épreuves'!$H$2:$H$5000,">="&TODAY())),"")
A21: UCI | B21: Cyclisme sur route | C21: UCI WorldTour | D21: 1 ligne par course | E21: https://www.uci.org | F21: =COUNTIF('Épreuves'!$C$2:$C$5000,C21) | G21: =IFERROR(1/(1/_xlfn.MINIFS('Épreuves'!$H$2:$H$5000,'Épreuves'!$C$2:$C$5000,C21,'Épreuves'!$H$2:$H$5000,">="&TODAY())),"")
A22: UCIM | B22: Cyclisme sur route | C22: Championnats du monde UCI | D22: 1 ligne par épreuve | E22: https://www.uci.org | F22: =COUNTIF('Épreuves'!$C$2:$C$5000,C22) | G22: =IFERROR(1/(1/_xlfn.MINIFS('Épreuves'!$H$2:$H$5000,'Épreuves'!$C$2:$C$5000,C22,'Épreuves'!$H$2:$H$5000,">="&TODAY())),"")
A23: SKI | B23: Ski alpin | C23: Coupe du monde de ski alpin | D23: 1 ligne par épreuve | E23: https://www.fis-ski.com | F23: =COUNTIF('Épreuves'!$C$2:$C$5000,C23) | G23: =IFERROR(1/(1/_xlfn.MINIFS('Épreuves'!$H$2:$H$5000,'Épreuves'!$C$2:$C$5000,C23,'Épreuves'!$H$2:$H$5000,">="&TODAY())),"")
A24: SKIM | B24: Ski alpin | C24: Championnats du monde de ski alpin | D24: 1 ligne par épreuve | E24: https://www.fis-ski.com | F24: =COUNTIF('Épreuves'!$C$2:$C$5000,C24) | G24: =IFERROR(1/(1/_xlfn.MINIFS('Épreuves'!$H$2:$H$5000,'Épreuves'!$C$2:$C$5000,C24,'Épreuves'!$H$2:$H$5000,">="&TODAY())),"")
A25: BIA | B25: Biathlon | C25: Coupe du monde de biathlon | D25: 1 ligne par épreuve | E25: https://www.biathlonworld.com | F25: =COUNTIF('Épreuves'!$C$2:$C$5000,C25) | G25: =IFERROR(1/(1/_xlfn.MINIFS('Épreuves'!$H$2:$H$5000,'Épreuves'!$C$2:$C$5000,C25,'Épreuves'!$H$2:$H$5000,">="&TODAY())),"")
A26: BIAM | B26: Biathlon | C26: Championnats du monde de biathlon | D26: 1 ligne par épreuve | E26: https://www.biathlonworld.com | F26: =COUNTIF('Épreuves'!$C$2:$C$5000,C26) | G26: =IFERROR(1/(1/_xlfn.MINIFS('Épreuves'!$H$2:$H$5000,'Épreuves'!$C$2:$C$5000,C26,'Épreuves'!$H$2:$H$5000,">="&TODAY())),"")
C27: Total | F27: =SUM(F2:F26)
